<?xml version="1.0"?>
<robot xmlns:controller="http://playerstage.sourceforge.net/gazebo/xmlschema/#controller"
       xmlns:interface="http://ros.org/wiki/xacro"
       xmlns:sensor="http://playerstage.sourceforge.net/gazebo/xmlschema/#sensor"
       xmlns:xacro="http://ros.org/wiki/xacro">


  <xacro:include filename="$(find kr5_description)/urdf/kr.transmission.xacro" />
  <xacro:include filename="$(find kr5_description)/urdf/kr.gazebo.xacro" />

  <!-- effort values can be found here: https://github.com/ros-industrial/universal_robot/issues/32-->

  <!-- plate Properties -->
  <!-- a plate with 40x40x1 (cm) -->
  <xacro:property name="plate_mass" value="0.5175" />
  <xacro:property name="plate_width" value="0.4" />

  <!-- Kinematic model -->
  <xacro:macro name="kr5_robot" params="prefix">

    <!-- links: -->
  <link name="dummy_link">
  </link>
  <joint name="dummy_joint" type="fixed">
    <origin rpy="0 0 0" xyz="0 0 0"/>
    <parent link="dummy_link"/>
    <child link="chassis"/>
  </joint>
  <link name="chassis">
    <inertial>
      <origin rpy="0 0 0" xyz="0 0 0"/>
      <mass value="29.7272547924329"/>
      <inertia ixx="0.449550486032544" ixy="-0.000202947299228558" ixz="4.02213748631659E-05" iyy="1.94429373714484" iyz="2.12270084680089E-06" izz="1.49783755191048"/>
    </inertial>
    <visual>
      <origin rpy="0 0 0" xyz="0 0 0"/>
      <geometry>
        <mesh filename="package://kr5_description/meshes/chassis.STL"/>
      </geometry>
      <material name="">
        <color rgba="0.529411764705882 0.549019607843137 0.549019607843137 1"/>
      </material>
    </visual>
    <collision>
      <origin rpy="0 0 0" xyz="0 0 0"/>
      <geometry>
        <mesh filename="package://kr5_description/meshes/chassis.STL"/>
      </geometry>
    </collision>
  </link>
  <link name="front_left_shaft">
    <inertial>
      <origin rpy="0 0 0" xyz="-0.0464226785971014 0.0446827881989769 4.89170259854177E-10"/>
      <mass value="2.24265737919929"/>
      <inertia ixx="0.00325725762466724" ixy="-0.00266183661888138" ixz="-1.80621812119859E-11" iyy="0.00626210496471374" iyz="2.88531798381733E-11" izz="0.00912627708840145"/>
    </inertial>
    <visual>
      <origin rpy="0 0 0" xyz="0 0 0"/>
      <geometry>
        <mesh filename="package://kr5_description/meshes/front_left_shaft.STL"/>
      </geometry>
      <material name="">
        <color rgba="0.529411764705882 0.549019607843137 0.549019607843137 1"/>
      </material>
    </visual>
    <collision>
      <origin rpy="0 0 0" xyz="0 0 0"/>
      <geometry>
        <mesh filename="package://kr5_description/meshes/front_left_shaft.STL"/>
      </geometry>
    </collision>
  </link>
  <joint name="front_left_shaft_joint" type="revolute">
    <origin rpy="1.5708 0 -1.5706" xyz="0.63139 -0.15492 0.24761"/>
    <parent link="chassis"/>
    <child link="front_left_shaft"/>
    <axis xyz="0 1 0"/>
    <limit effort="1" lower="-0.3" upper="0.3" velocity="10"/>
  </joint>
  <link name="front_left_wheel">
    <inertial>
      <origin rpy="0 0 0" xyz="-0.0255257353143014 2.33146835171283E-15 -2.72004641033163E-15"/>
      <mass value="8.76629013800866"/>
      <inertia ixx="0.0519708588840021" ixy="-2.16658724754091E-15" ixz="2.53797413722048E-15" iyy="0.0278572070595198" iyz="-1.8753639652371E-17" izz="0.0278572070595198"/>
    </inertial>
    <visual>
      <origin rpy="0 0 0" xyz="0 0 0"/>
      <geometry>
        <mesh filename="package://kr5_description/meshes/front_left_wheel.STL"/>
      </geometry>
      <material name="">
        <color rgba="0.529411764705882 0.549019607843137 0.549019607843137 1"/>
      </material>
    </visual>
    <collision>
      <origin rpy="0 0 0" xyz="0 0 0"/>
      <geometry>
        <mesh filename="package://kr5_description/meshes/front_left_wheel.STL"/>
      </geometry>
    </collision>
  </link>
  <joint name="front_left_wheel_joint" type="continuous">
    <origin rpy="2.4564 0 0" xyz="-0.10508 0.01905 0"/>
    <parent link="front_left_shaft"/>
    <child link="front_left_wheel"/>
    <axis xyz="1 0 0"/>
    <limit effort="10" velocity="1000"/>
  </joint>
  <link name="front_right_shaft">
    <inertial>
      <origin rpy="0 0 0" xyz="-0.0464226788201876 0.0446827888000026 6.50812626012964E-10"/>
      <mass value="2.24265734987251"/>
      <inertia ixx="0.00325725762619304" ixy="-0.00266183671566097" ixz="-2.65483127323519E-11" iyy="0.00626210498349088" iyz="3.25700991581101E-11" izz="0.00912627711111106"/>
    </inertial>
    <visual>
      <origin rpy="0 0 0" xyz="0 0 0"/>
      <geometry>
        <mesh filename="package://kr5_description/meshes/front_right_shaft.STL"/>
      </geometry>
      <material name="">
        <color rgba="0.529411764705882 0.549019607843137 0.549019607843137 1"/>
      </material>
    </visual>
    <collision>
      <origin rpy="0 0 0" xyz="0 0 0"/>
      <geometry>
        <mesh filename="package://kr5_description/meshes/front_right_shaft.STL"/>
      </geometry>
    </collision>
  </link>
  <joint name="front_right_shaft_joint" type="revolute">
    <origin rpy="1.5708 0 1.5592" xyz="0.63139 -0.49375 0.24761"/>
    <parent link="chassis"/>
    <child link="front_right_shaft"/>
    <axis xyz="0 1 0"/>
    <limit effort="1" lower="-0.3" upper="0.3" velocity="10"/>
  </joint>
  <link name="front_right_wheel">
    <inertial>
      <origin rpy="0 0 0" xyz="0.0254625877960101 6.66133814775094E-16 -6.93889390390723E-17"/>
      <mass value="8.76629013800866"/>
      <inertia ixx="0.0519708588840022" ixy="4.9287830761191E-16" ixz="-9.4142629889632E-17" iyy="0.0278572070595198" iyz="-1.58818677610181E-17" izz="0.0278572070595199"/>
    </inertial>
    <visual>
      <origin rpy="0 0 0" xyz="0 0 0"/>
      <geometry>
        <mesh filename="package://kr5_description/meshes/front_right_wheel.STL"/>
      </geometry>
      <material name="">
        <color rgba="0.529411764705882 0.549019607843137 0.549019607843137 1"/>
      </material>
    </visual>
    <collision>
      <origin rpy="0 0 0" xyz="0 0 0"/>
      <geometry>
        <mesh filename="package://kr5_description/meshes/front_right_wheel.STL"/>
      </geometry>
    </collision>
  </link>
  <joint name="front_right_wheel_joint" type="continuous">
    <origin rpy="-1.3309 0 3.1416" xyz="-0.10503 0.01905 0"/>
    <parent link="front_right_shaft"/>
    <child link="front_right_wheel"/>
    <axis xyz="1 0 0"/>
    <limit effort="10" velocity="1000"/>
  </joint>
  <link name="rear_left_shaft">
    <inertial>
      <origin rpy="0 0 0" xyz="-0.0464226785931731 0.042185211811601 -4.919547408333E-10"/>
      <mass value="2.24265737971412"/>
      <inertia ixx="0.00325725762464155" ixy="0.0026618366171779" ixz="1.8210941713322E-11" iyy="0.00626210496438074" iyz="2.89166451766443E-11" izz="0.00912627708800206"/>
    </inertial>
    <visual>
      <origin rpy="0 0 0" xyz="0 0 0"/>
      <geometry>
        <mesh filename="package://kr5_description/meshes/rear_left_shaft.STL"/>
      </geometry>
      <material name="">
        <color rgba="0.529411764705882 0.549019607843137 0.549019607843137 1"/>
      </material>
    </visual>
    <collision>
      <origin rpy="0 0 0" xyz="0 0 0"/>
      <geometry>
        <mesh filename="package://kr5_description/meshes/rear_left_shaft.STL"/>
      </geometry>
    </collision>
  </link>
  <joint name="rear_left_shaft_joint" type="fixed">
    <origin rpy="-1.5708 0 -1.5708" xyz="0.12339 -0.15492 0.33448"/>
    <parent link="chassis"/>
    <child link="rear_left_shaft"/>
    <axis xyz="0 0 0"/>
    
  </joint>
  <link name="rear_left_wheel">
    <inertial>
      <origin rpy="0 0 0" xyz="-0.0254680962112496 -4.16333634234434E-17 -5.55111512312578E-17"/>
      <mass value="8.76629013800865"/>
      <inertia ixx="0.0519708588840021" ixy="2.96511607446582E-19" ixz="2.10626832882971E-18" iyy="0.0278572070595198" iyz="-1.38777878078145E-17" izz="0.0278572070595198"/>
    </inertial>
    <visual>
      <origin rpy="0 0 0" xyz="0 0 0"/>
      <geometry>
        <mesh filename="package://kr5_description/meshes/rear_left_wheel.STL"/>
      </geometry>
      <material name="">
        <color rgba="0.529411764705882 0.549019607843137 0.549019607843137 1"/>
      </material>
    </visual>
    <collision>
      <origin rpy="0 0 0" xyz="0 0 0"/>
      <geometry>
        <mesh filename="package://kr5_description/meshes/rear_left_wheel.STL"/>
      </geometry>
    </collision>
  </link>
  <joint name="rear_left_wheel_joint" type="continuous">
    <origin rpy="-1.9862 0 0" xyz="-0.10502 0.067818 0"/>
    <parent link="rear_left_shaft"/>
    <child link="rear_left_wheel"/>
    <axis xyz="1 0 0"/>
    <limit effort="10" velocity="1000"/>
  </joint>
  <link name="rear_right_shaft">
    <inertial>
      <origin rpy="0 0 0" xyz="-0.0464226785931731 -0.042185211811601 4.91954713077725E-10"/>
      <mass value="2.24265737971412"/>
      <inertia ixx="0.00325725762464156" ixy="-0.0026618366171779" ixz="-1.8210940473168E-11" iyy="0.00626210496438074" iyz="2.89166447648455E-11" izz="0.00912627708800207"/>
    </inertial>
    <visual>
      <origin rpy="0 0 0" xyz="0 0 0"/>
      <geometry>
        <mesh filename="package://kr5_description/meshes/rear_right_shaft.STL"/>
      </geometry>
      <material name="">
        <color rgba="0.529411764705882 0.549019607843137 0.549019607843137 1"/>
      </material>
    </visual>
    <collision>
      <origin rpy="0 0 0" xyz="0 0 0"/>
      <geometry>
        <mesh filename="package://kr5_description/meshes/rear_right_shaft.STL"/>
      </geometry>
    </collision>
  </link>
  <joint name="rear_right_shaft_joint" type="fixed">
    <origin rpy="1.5708 0 1.5708" xyz="0.12339 -0.49375 0.33448"/>
    <parent link="chassis"/>
    <child link="rear_right_shaft"/>
    <axis xyz="0 0 0"/>
  </joint>
  <link name="rear_right_wheel">
    <inertial>
      <origin rpy="0 0 0" xyz="0.0254694168183411 0 -2.77555756156289E-17"/>
      <mass value="8.76629013800868"/>
      <inertia ixx="0.0519708588840023" ixy="-3.9276678022605E-19" ixz="2.08848630701201E-19" iyy="0.0278572070595199" iyz="-1.36609473733174E-17" izz="0.0278572070595199"/>
    </inertial>
    <visual>
      <origin rpy="0 0 0" xyz="0 0 0"/>
      <geometry>
        <mesh filename="package://kr5_description/meshes/rear_right_wheel.STL"/>
      </geometry>
      <material name="">
        <color rgba="0.529411764705882 0.549019607843137 0.549019607843137 1"/>
      </material>
    </visual>
    <collision>
      <origin rpy="0 0 0" xyz="0 0 0"/>
      <geometry>
        <mesh filename="package://kr5_description/meshes/rear_right_wheel.STL"/>
      </geometry>
    </collision>
  </link>
  <joint name="rear_right_wheel_joint" type="continuous">
    <origin rpy="-0.11861 0 3.1416" xyz="-0.10514 -0.067818 0"/>
    <parent link="rear_right_shaft"/>
    <child link="rear_right_wheel"/>
    <axis xyz="1 0 0"/>
    <limit effort="10" velocity="1000"/>
  </joint>
  <transmission name="front_right_transmission">
    <type>transmission_interface/SimpleTransmission</type>
    <joint name="front_right_shaft_joint">
      <hardwareInterface>hardware_interface/EffortJointInterface</hardwareInterface>
    </joint>
    <actuator name="front_right_motor">
      <hardwareInterface>hardware_interface/EffortJointInterface</hardwareInterface>
      <mechanicalReduction>1</mechanicalReduction>
    </actuator>
  </transmission>
  <transmission name="front_left_transmission">
    <type>transmission_interface/SimpleTransmission</type>
    <joint name="front_left_shaft_joint">
      <hardwareInterface>hardware_interface/EffortJointInterface</hardwareInterface>
    </joint>
    <actuator name="front_left_motor">
      <hardwareInterface>hardware_interface/EffortJointInterface</hardwareInterface>
      <mechanicalReduction>1</mechanicalReduction>
    </actuator>
  </transmission>
  <transmission name="rear_right_transmission">
    <type>transmission_interface/SimpleTransmission</type>
    <joint name="rear_right_wheel_joint">
      <hardwareInterface>hardware_interface/EffortJointInterface</hardwareInterface>
    </joint>
    <actuator name="rear_right_motor">
      <hardwareInterface>hardware_interface/EffortJointInterface</hardwareInterface>
      <mechanicalReduction>1</mechanicalReduction>
    </actuator>
  </transmission>
  <transmission name="rear_left_transmission">
    <type>transmission_interface/SimpleTransmission</type>
    <joint name="rear_left_wheel_joint">
      <hardwareInterface>hardware_interface/EffortJointInterface</hardwareInterface>
    </joint>
    <actuator name="rear_left_motor">
      <hardwareInterface>hardware_interface/EffortJointInterface</hardwareInterface>
      <mechanicalReduction>1</mechanicalReduction>
    </actuator>
  </transmission>

    <joint name="robo_arm_joint" type="fixed">
      <origin rpy="0 0 0" xyz="0.35 -0.32 0.38"/>
      <parent link="chassis"/>
      <child link="${prefix}base_link"/>
      <axis xyz="0 0 0"/>
    </joint>

    <link name="${prefix}base_link" >
    <inertial>
       <origin xyz="0 1 1" rpy="0 0 0" />
       <mass value="7.58585707666653" />
       <!-- changed mass! 7000? -->
       <inertia ixx="0.0441803207364147" ixy="5.37433593375545E-07" ixz="0.004045564920652" iyy="0.0584309411563095" iyz="-4.8990117845347E-07" izz="0.0514875586171667" />
    </inertial>
      <visual>
        <origin rpy="0 0 0" xyz="0 0 0" />
        <geometry>
          <mesh filename="package://kr5_description/meshes/visual/base_link.dae" />
        </geometry>
      </visual>
      <collision>
        <origin rpy="0 0 0" xyz="0 0 0" />
        <geometry>
          <mesh filename="package://kr5_description/meshes/visual/base_link.dae" />
        </geometry>
      </collision>
    </link>

    <link name="${prefix}link_1">
    <inertial>
       <origin xyz="0.0359968408135882 0.00783796591813503 -0.0864969937502713" rpy="0 0 0" />
       <mass value="5.77242340173648" />
       <inertia ixx="0.0327019582662897" ixy="-0.00189987845379704" ixz="0.00937014136132958" iyy="0.0373787564144547" iyz="-0.00197023031658988" izz="0.0348614383349291" />
    </inertial>
      <visual>
                  <origin rpy="0 0 0" xyz="0 0 0" />
        <geometry>
          <mesh filename="package://kr5_description/meshes/visual/link_1.dae" />
        </geometry>
      </visual>
      <collision>
                  <origin rpy="0 0 0" xyz="0 0 0" />
        <geometry>
          <mesh filename="package://kr5_description/meshes/collision/link_1.stl" />
        </geometry>
      </collision>
    </link>

    <link name="${prefix}link_2">
    <inertial>
       <origin xyz="0.00610231661046294 0.0401115026555897 -0.11531122862673" rpy="0 0 0" />
       <mass value="4.64974639735464" />
       <inertia ixx="0.0663459530931455" ixy="0.000173652478770081" ixz="0.000586191290902105" iyy="0.070407913174161" iyz="-0.00203071071007864" izz="0.0102816377550493" />
    </inertial>
      <visual>
        <origin xyz="0 0 0" rpy="0 0 0" />
        <geometry>
          <mesh filename="package://kr5_description/meshes/visual/link_2.dae" />
         </geometry>
      </visual>
      <collision>
        <origin xyz="0 0 0" rpy="0 0 0" />
        <geometry>
          <mesh filename="package://kr5_description/meshes/collision/link_2.stl" />
        </geometry>
      </collision>
    </link>

    <link name="${prefix}link_3">
    <inertial>
       <origin xyz="0.0755031858462784 -0.046481517407519 -0.00506472105904233" rpy="0 0 0" />
       <mass value="4.3593398708568" />
       <inertia ixx="0.0202008069207718" ixy="5.72394748332304E-05" ixz="0.000556621203065716" iyy="0.0246796752429931" iyz="0.000697020296811431" izz="0.0178067561136726" />
    </inertial>
      <visual>
                  <origin rpy="0 0 0" xyz="0 0 0" />
        <geometry>
            <mesh filename="package://kr5_description/meshes/visual/link_3.dae" />
        </geometry>
        <material name="LightGrey">
          <color rgba="0.7 0.7 0.7 1.0"/>
        </material>
      </visual>
      <collision>
                  <origin rpy="0 0 0" xyz="0 0 0" />
        <geometry>
          <mesh filename="package://kr5_description/meshes/collision/link_3.stl" />
            </geometry>
      </collision>
    </link>

    <!-- wrist links: -->
    <link name="${prefix}link_4">
    <inertial>
       <origin xyz="0.0857493724873204 -0.00149370513017266 -0.00271609825446984" rpy="0 0 0" />
       <mass value="2.06809715541017" />
       <inertia ixx="0.00444943757623485" ixy="-0.000424915429214687" ixz="-0.000117340671961173" iyy="0.00882693069799353" iyz="0.000136971152627904" izz="0.0101131228921778" />
    </inertial>
      <visual>
                  <origin rpy="0 0 0" xyz="0 0 0" />
        <geometry>
          <mesh filename="package://kr5_description/meshes/visual/link_4.dae" />
             </geometry>
        <material name="LightGrey">
          <color rgba="0.7 0.7 0.7 1.0"/>
        </material>
      </visual>
      <collision>
                  <origin rpy="0 0 0" xyz="0 0 0" />
        <geometry>
          <mesh filename="package://kr5_description/meshes/collision/link_4.stl" />
              </geometry>
      </collision>
    </link>

    <link name="${prefix}link_5">
    <inertial>
       <origin xyz="0 0 0" rpy="0 0 0" />
       <mass value="0.328309098974388" />
       <inertia ixx="0.000221789219477276" ixy="-9.59628913869705E-07" ixz="1.40395663663479E-20" iyy="0.000321152451627032" iyz="-4.44973606670705E-20" izz="0.000275966419870925" />
    </inertial>
      <visual>
                  <origin rpy="0 0 0" xyz="0 0 0" />
        <geometry>
          <mesh filename="package://kr5_description/meshes/collision/link_5.stl" />
          </geometry>
        <material name="LightGrey">
          <color rgba="0.7 0.7 0.7 1.0"/>
        </material>
      </visual>
      <collision>
                  <origin rpy="0 0 0" xyz="0 0 0" />
        <geometry>
          <mesh filename="package://kr5_description/meshes/collision/link_5.stl" />
            </geometry>
      </collision>
    </link>

    <link name="${prefix}link_6">
    <inertial>
       <origin xyz="0.00983949894991115 -2.78372724487979E-05 -1.11022302462516E-15" rpy="0 0 0" />
       <mass value="0.0789494717998531" />
       <inertia ixx="3.53285039019399E-05" ixy="-3.23299732456798E-08" ixz="-6.9643163510009E-19" iyy="2.30177957763861E-05" iyz="-9.26550270485857E-19" izz="2.28539400944714E-05" />
    </inertial>
      <visual>
                  <origin rpy="0 0 0" xyz="0 0 0" />
        <geometry>
          <mesh filename="package://kr5_description/meshes/visual/link_6.dae" />
         </geometry>
        <material name="LightGrey">
          <color rgba="0.7 0.7 0.7 1.0"/>
        </material>
      </visual>
      <collision>
                  <origin rpy="0 0 0" xyz="0 0 0" />
        <geometry>
          <mesh filename="package://kr5_description/meshes/collision/link_6.stl" />
           </geometry>
      </collision>
    </link>

  <!-- tool link -->
  <!-- This frame corresponds to the $FLANGE coordinate system in KUKA KRC controllers. -->
  <xacro:if value="$(arg use_the_plate)">
     <link name="${prefix}ee_link">
        <inertial>
           <origin xyz="0.00983949894991115 -2.78372724487979E-05 -1.11022302462516E-15" rpy="0 0 0" />
           <mass value="${plate_mass}" />
           <inertia ixx="0.0138" ixy="0" ixz="0" iyy="0.0138" iyz="0" izz="0.0217" /> <!-- ${0.08333333333*plate_mass*plate_width}-->
        </inertial>
        <visual>
           <origin xyz="0 0 0" rpy="0 0 0" />
           <geometry>
              <mesh filename="package://kr5_description/meshes/tools/plate_40.stl" scale="0.01 0.01 0.01" /> <!-- plate is 20x20x1cm if scale is 0.01 -->
           </geometry>
        </visual>
        <collision>
           <origin xyz="0 0 0" rpy="0 0 0" />
           <geometry>
              <mesh filename="package://kr5_description/meshes/tools/plate_40.stl" scale="0.01 0.01 0.01" /> <!-- plate is 20x20x1 m -->
           </geometry>
        </collision>
     </link>
  </xacro:if>

  <!-- joints: -->
  <joint name="${prefix}joint_a1" type="revolute">
    <origin xyz="0 0 0.4" rpy="${pi} 0 0" />
    <parent link="${prefix}base_link" />
    <child link = "${prefix}link_1" />
    <axis xyz="0 0 1" />
    <limit effort="150" lower="${radians(-155)}" upper="${radians(155)}" velocity="${radians(154)}" />
    <dynamics damping="0.0" friction="0.0"/>
  </joint>


    <joint name="${prefix}joint_a2" type="revolute">
      <origin xyz="0.18 0 0" rpy="${pi/2} 0.0 0" />
      <parent link="${prefix}link_1" />
      <child link = "${prefix}link_2" />
      <axis xyz="0 0 1" />
      <limit  lower="${radians(-180)}" upper="${radians(65)}" effort="150.0" velocity="${radians(154)}"/>
      <dynamics damping="0.0" friction="0.0"/>
    </joint>

    <joint name="${prefix}joint_a3" type="revolute">
    <parent link="${prefix}link_2" />
    <child link = "${prefix}link_3" />
    <origin xyz="0.6 0 0" rpy="0 0 0" />
      <axis xyz="0 0 1" />
      <limit lower="${radians(-15)}" upper="${radians(158)}"  effort="150.0" velocity="3.15"/>
      <dynamics damping="0.0" friction="0.0"/>
    </joint>

    <joint name="${prefix}joint_a4" type="revolute">
    <parent link="${prefix}link_3" />
    <child link = "${prefix}link_4" />
         <origin xyz="0 -0.12 0" rpy="0 ${-pi/2} 0" />
      <axis xyz="0 0 1" />
      <limit lower="${radians(-350)}" upper="${radians(350)}" effort="60.0" velocity="3.2"/> <!-- max should be 28 -->
      <dynamics damping="0.0" friction="0.0"/>
    </joint>

    <joint name="${prefix}joint_a5" type="revolute">
    <parent link="${prefix}link_4" />
    <child link = "${prefix}link_5" />
         <origin xyz="0 0 -0.62" rpy="0 ${pi/2} 0" />
      <axis xyz="0 0 1" />
      <limit  lower="${radians(-130)}" upper="${radians(130)}" effort="60.0" velocity="3.2"/> <!-- max should be 28 -->
      <dynamics damping="0.0" friction="0.0"/>
    </joint>

    <joint name="${prefix}joint_a6" type="revolute">
    <parent link="${prefix}link_5" />
    <child link = "${prefix}link_6" />
         <origin xyz="0 0 0" rpy="0 ${-pi/2} 0" />
      <axis xyz="0 0 1" />
      <limit lower="${radians(-350)}" upper="${radians(350)}"  effort="28.0" velocity="3.2"/>
      <dynamics damping="0.0" friction="0.0"/>
    </joint>

    <joint name="${prefix}ee_fixed_joint" type="fixed">
      <parent link="${prefix}link_6" />
      <child link = "${prefix}ee_link" />
      <origin xyz="0 0 -0.115" rpy="0 ${-pi} ${-pi/2}" />
    </joint>


    <xacro:kr_arm_transmission prefix="${prefix}" />
    <xacro:kr_arm_gazebo prefix="${prefix}" />

    <!-- ROS base_link to UR 'Base' Coordinates transform -->
    <link name="${prefix}base"/>
    <joint name="${prefix}base_link-base_fixed_joint" type="fixed">
      <!-- NOTE: this rotation is only needed as long as base_link itself is
                 not corrected wrt the real robot (ie: rotated over 180
                 degrees)
      -->
      <origin xyz="0 0 0" rpy="0 0 ${-pi}"/>
      <parent link="${prefix}base_link"/>
      <child link="${prefix}base"/>
    </joint>

    <!-- Frame coincident with all-zeros TCP on UR controller -->
    <link name="${prefix}tool0"/>
    <joint name="${prefix}wrist_3_link-tool0_fixed_joint" type="fixed">
      <origin xyz="0 0.115 0" rpy="${pi/-2.0} 0 0"/>
      <parent link="${prefix}link_6"/>
      <child link="${prefix}tool0"/>
    </joint>

  </xacro:macro>
</robot>
